# 예외 반환하기

try-catch문 말고도 예외를 처리하는 방법이 있다.

메소드에서 예외 타입을 반환하여 던지는 경우가 있다.

```java
public class playGround {
  public static void play() {
    int a = 0;
    try{
      checkNum(a);
      System.out.println(100 / a);
    }catch (ArithmeticException e){
      System.out.println(e.getMessage());
    }
  }
  static void checkNum(int a) throws ArithmeticException{
    if (a == 0){
      throw new ArithmeticException("Can't be divided by 0");
    }
    System.out.println("Continue");
  }
}
// Can't be divided by 0
```

`checkNum()`메소드가 `int a`의 값에 따라 예외처리를 하는 것을 볼 수 있다.

이때, 

```java
void checkNum(int a) throws ArithmeticException {}
```

와 같은 구문으로 반환하려는 예외 타입을 명시할 수 있다. 여러개를 명시 할 수 있다.

주의할 점은, 이 메소드를 오버라이딩하는 경우이다. 오버라이딩의 경우 조상보다 많은 예외선언은 불가하기 때문에,

```java
class Child extends Parent{
  void checkNum(int a, int b) throws Exception{}; //Override 불가
}
```

와 같은 결과가 나타날 수 있다.  `Exception`은 모든 예외타입의 부모이기 때문에, 선언된 갯수는 하나이지만 실제 반환할 수 있는 예외가 많다는 점을 주의하자.



### 사용자 정의 예외

Java에서 제공하는 예외타입 이외의 예외들을 선언할 수 있다.

```java
class OverNumberException extends Exception{ //Exception을 상속받았기 때문에 반드시 예외처리 필요
    OverNumberException(String errMessage) {
        super(errMessage);
    }
}
public class playGround {
    public static void play() {
        int a = 1000;
        try{
            checkNum(a);
            System.out.println(100 / a);
        }catch (OverNumberException e){
            System.out.println(e.getMessage());
        }

    }
    static void checkNum(int a) throws OverNumberException {
        if (a > 100){
            throw new OverNumberException("Over Value"); //--1
        }
        System.out.println("Continue");
    }
}
```

`OverNumberException`라는 예외를 하나 만들었다. 예외의 최고 조상인 `Exception`을 상속받고,

여러 메소드들을 통해 예외타입을 다룰 수 있다. 이 예제에서는 `super()`생성자를 통해 `--1`을 구현했다.



### 예외 연결하기

예외들간에도 관계들이 있을 것이다. 

`OverNumberExcpetion()`, `LowerNumberExcpetion()`이라는 예외는 `WrongNumberExcepction()`이라고 묶을 수 있을 것이다.

어떠한 예외의 원인인 예외들의 관계를 통해 보다 정확화게 예외를 파악할 수 있다.

```java
package playground;
class OverNumberException extends Exception{
    OverNumberException(String errMessage) {
        super(errMessage);
    }
}
class UnderNumberException extends Exception{
    UnderNumberException(String errMessage) {
        super(errMessage);
    }
}
class WrongNumberException extends Exception{
    WrongNumberException(String errMessage) {
        super(errMessage);
    }
}
public class playGround {
    public static void play(){
        try{
            playForException();
        }catch (WrongNumberException e){
            e.printStackTrace();
        }
    }
    static void playForException() throws WrongNumberException {
        int a = 1000;
        try{
            checkNum(a);
            System.out.println(100 / a);
        }catch (OverNumberException | ArithmeticException | UnderNumberException e){
            WrongNumberException we = new WrongNumberException("Wrong Number Value");
            we.initCause(e);  // --1
            throw we;
        }
    }
    static void checkNum(int a) throws OverNumberException, ArithmeticException, UnderNumberException {
        if (a > 100){
            throw new OverNumberException("Over Value");
        }
        if (a == 0){
            throw new ArithmeticException("Zero Value");
        }
        if (a < 0){
            throw new UnderNumberException("Under Value");
        }
        System.out.println("Continue");
    }
}
// 실행 결과.
// a > 100이므로
// OverNumberException
// -> WrongNumberException의 원인이 됨. // .initCause(e)
// e.printStackTrace();

/*
playground.WrongNumberException: Wrong Number Value
	at playground.playGround.playForException(playGround.java:31)
	at playground.playGround.play(playGround.java:20)
	at playground.main.main(main.java:6)
Caused by: playground.OverNumberException: Over Value
	at playground.playGround.checkNum(playGround.java:38)
	at playground.playGround.playForException(playGround.java:28)
	... 2 more
*/
```

예외들을 연결시켜, `WrongNumberValue`가 `OverValue`에 의해 일어났다는 것을 알 수 있다.